[2015-09-15 22:00:30,174] [ERROR] base : Internal Server Error: /
Traceback (most recent call last):
  File "/usr/local/lib/python2.7/dist-packages/django/core/handlers/base.py", line 132, in get_response
    response = wrapped_callback(request, *callback_args, **callback_kwargs)
  File "/usr/local/lib/python2.7/dist-packages/django/views/generic/base.py", line 71, in view
    return self.dispatch(request, *args, **kwargs)
  File "/usr/local/lib/python2.7/dist-packages/django/views/generic/base.py", line 89, in dispatch
    return handler(request, *args, **kwargs)
  File "/usr/local/lib/python2.7/dist-packages/django/views/generic/list.py", line 174, in get
    context = self.get_context_data()
  File "/root/levysys/FBC3/blog/views.py", line 61, in get_context_data
  File "/root/levysys/FBC3/blog/views.py", line 36, in get_context_data
  File "/usr/local/lib/python2.7/dist-packages/django/views/generic/list.py", line 134, in get_context_data
    paginator, page, queryset, is_paginated = self.paginate_queryset(queryset, page_size)
  File "/usr/local/lib/python2.7/dist-packages/django/views/generic/list.py", line 78, in paginate_queryset
    page = paginator.page(page_number)
  File "/usr/local/lib/python2.7/dist-packages/django/core/paginator.py", line 50, in page
    number = self.validate_number(number)
  File "/usr/local/lib/python2.7/dist-packages/django/core/paginator.py", line 39, in validate_number
    if number > self.num_pages:
  File "/usr/local/lib/python2.7/dist-packages/django/core/paginator.py", line 86, in _get_num_pages
    if self.count == 0 and not self.allow_empty_first_page:
  File "/usr/local/lib/python2.7/dist-packages/django/core/paginator.py", line 72, in _get_count
    self._count = self.object_list.count()
  File "/usr/local/lib/python2.7/dist-packages/django/db/models/query.py", line 318, in count
    return self.query.get_count(using=self.db)
  File "/usr/local/lib/python2.7/dist-packages/django/db/models/sql/query.py", line 464, in get_count
    number = obj.get_aggregation(using, ['__count'])['__count']
  File "/usr/local/lib/python2.7/dist-packages/django/db/models/sql/query.py", line 445, in get_aggregation
    result = compiler.execute_sql(SINGLE)
  File "/usr/local/lib/python2.7/dist-packages/django/db/models/sql/compiler.py", line 838, in execute_sql
    cursor = self.connection.cursor()
  File "/usr/local/lib/python2.7/dist-packages/django/db/backends/base/base.py", line 164, in cursor
    cursor = self.make_cursor(self._cursor())
  File "/usr/local/lib/python2.7/dist-packages/django/db/backends/base/base.py", line 135, in _cursor
    self.ensure_connection()
  File "/usr/local/lib/python2.7/dist-packages/django/db/backends/base/base.py", line 130, in ensure_connection
    self.connect()
  File "/usr/local/lib/python2.7/dist-packages/django/db/utils.py", line 97, in __exit__
    six.reraise(dj_exc_type, dj_exc_value, traceback)
  File "/usr/local/lib/python2.7/dist-packages/django/db/backends/base/base.py", line 130, in ensure_connection
    self.connect()
  File "/usr/local/lib/python2.7/dist-packages/django/db/backends/base/base.py", line 119, in connect
    self.connection = self.get_new_connection(conn_params)
  File "/usr/local/lib/python2.7/dist-packages/django/db/backends/sqlite3/base.py", line 204, in get_new_connection
    conn = Database.connect(**conn_params)
OperationalError: unable to open database file
[2015-09-15 22:00:30,174] [ERROR] base : Internal Server Error: /
Traceback (most recent call last):
  File "/usr/local/lib/python2.7/dist-packages/django/core/handlers/base.py", line 132, in get_response
    response = wrapped_callback(request, *callback_args, **callback_kwargs)
  File "/usr/local/lib/python2.7/dist-packages/django/views/generic/base.py", line 71, in view
    return self.dispatch(request, *args, **kwargs)
  File "/usr/local/lib/python2.7/dist-packages/django/views/generic/base.py", line 89, in dispatch
    return handler(request, *args, **kwargs)
  File "/usr/local/lib/python2.7/dist-packages/django/views/generic/list.py", line 174, in get
    context = self.get_context_data()
  File "/root/levysys/FBC3/blog/views.py", line 61, in get_context_data
  File "/root/levysys/FBC3/blog/views.py", line 36, in get_context_data
  File "/usr/local/lib/python2.7/dist-packages/django/views/generic/list.py", line 134, in get_context_data
    paginator, page, queryset, is_paginated = self.paginate_queryset(queryset, page_size)
  File "/usr/local/lib/python2.7/dist-packages/django/views/generic/list.py", line 78, in paginate_queryset
    page = paginator.page(page_number)
  File "/usr/local/lib/python2.7/dist-packages/django/core/paginator.py", line 50, in page
    number = self.validate_number(number)
  File "/usr/local/lib/python2.7/dist-packages/django/core/paginator.py", line 39, in validate_number
    if number > self.num_pages:
  File "/usr/local/lib/python2.7/dist-packages/django/core/paginator.py", line 86, in _get_num_pages
    if self.count == 0 and not self.allow_empty_first_page:
  File "/usr/local/lib/python2.7/dist-packages/django/core/paginator.py", line 72, in _get_count
    self._count = self.object_list.count()
  File "/usr/local/lib/python2.7/dist-packages/django/db/models/query.py", line 318, in count
    return self.query.get_count(using=self.db)
  File "/usr/local/lib/python2.7/dist-packages/django/db/models/sql/query.py", line 464, in get_count
    number = obj.get_aggregation(using, ['__count'])['__count']
  File "/usr/local/lib/python2.7/dist-packages/django/db/models/sql/query.py", line 445, in get_aggregation
    result = compiler.execute_sql(SINGLE)
  File "/usr/local/lib/python2.7/dist-packages/django/db/models/sql/compiler.py", line 838, in execute_sql
    cursor = self.connection.cursor()
  File "/usr/local/lib/python2.7/dist-packages/django/db/backends/base/base.py", line 164, in cursor
    cursor = self.make_cursor(self._cursor())
  File "/usr/local/lib/python2.7/dist-packages/django/db/backends/base/base.py", line 135, in _cursor
    self.ensure_connection()
  File "/usr/local/lib/python2.7/dist-packages/django/db/backends/base/base.py", line 130, in ensure_connection
    self.connect()
  File "/usr/local/lib/python2.7/dist-packages/django/db/utils.py", line 97, in __exit__
    six.reraise(dj_exc_type, dj_exc_value, traceback)
  File "/usr/local/lib/python2.7/dist-packages/django/db/backends/base/base.py", line 130, in ensure_connection
    self.connect()
  File "/usr/local/lib/python2.7/dist-packages/django/db/backends/base/base.py", line 119, in connect
    self.connection = self.get_new_connection(conn_params)
  File "/usr/local/lib/python2.7/dist-packages/django/db/backends/sqlite3/base.py", line 204, in get_new_connection
    conn = Database.connect(**conn_params)
OperationalError: unable to open database file
[2015-09-15 22:54:11,005] [ERROR] base : Internal Server Error: /media/static/carousel/1.jpg
Traceback (most recent call last):
  File "/usr/local/lib/python2.7/dist-packages/django/core/handlers/base.py", line 108, in get_response
    response = middleware_method(request)
  File "/usr/local/lib/python2.7/dist-packages/django/middleware/common.py", line 74, in process_request
    if (not urlresolvers.is_valid_path(request.path_info, urlconf) and
  File "/usr/local/lib/python2.7/dist-packages/django/core/urlresolvers.py", line 647, in is_valid_path
    resolve(path, urlconf)
  File "/usr/local/lib/python2.7/dist-packages/django/core/urlresolvers.py", line 522, in resolve
    return get_resolver(urlconf).resolve(path)
  File "/usr/local/lib/python2.7/dist-packages/django/core/urlresolvers.py", line 366, in resolve
    for pattern in self.url_patterns:
  File "/usr/local/lib/python2.7/dist-packages/django/core/urlresolvers.py", line 402, in url_patterns
    patterns = getattr(self.urlconf_module, "urlpatterns", self.urlconf_module)
  File "/usr/local/lib/python2.7/dist-packages/django/core/urlresolvers.py", line 396, in urlconf_module
    self._urlconf_module = import_module(self.urlconf_name)
  File "/usr/lib/python2.7/importlib/__init__.py", line 37, in import_module
    __import__(name)
  File "/root/levysys/vmaig_blog/vmaig_blog/urls.py", line 14, in <module>
    url(r'^media/(?P<path>.*)$','django.views.static.serve',{'document_root':setting.MEDIA_ROOT}),
NameError: name 'setting' is not defined
[2015-09-15 22:54:11,005] [ERROR] base : Internal Server Error: /media/static/carousel/1.jpg
Traceback (most recent call last):
  File "/usr/local/lib/python2.7/dist-packages/django/core/handlers/base.py", line 108, in get_response
    response = middleware_method(request)
  File "/usr/local/lib/python2.7/dist-packages/django/middleware/common.py", line 74, in process_request
    if (not urlresolvers.is_valid_path(request.path_info, urlconf) and
  File "/usr/local/lib/python2.7/dist-packages/django/core/urlresolvers.py", line 647, in is_valid_path
    resolve(path, urlconf)
  File "/usr/local/lib/python2.7/dist-packages/django/core/urlresolvers.py", line 522, in resolve
    return get_resolver(urlconf).resolve(path)
  File "/usr/local/lib/python2.7/dist-packages/django/core/urlresolvers.py", line 366, in resolve
    for pattern in self.url_patterns:
  File "/usr/local/lib/python2.7/dist-packages/django/core/urlresolvers.py", line 402, in url_patterns
    patterns = getattr(self.urlconf_module, "urlpatterns", self.urlconf_module)
  File "/usr/local/lib/python2.7/dist-packages/django/core/urlresolvers.py", line 396, in urlconf_module
    self._urlconf_module = import_module(self.urlconf_name)
  File "/usr/lib/python2.7/importlib/__init__.py", line 37, in import_module
    __import__(name)
  File "/root/levysys/vmaig_blog/vmaig_blog/urls.py", line 14, in <module>
    url(r'^media/(?P<path>.*)$','django.views.static.serve',{'document_root':setting.MEDIA_ROOT}),
NameError: name 'setting' is not defined
[2015-09-15 22:54:22,412] [ERROR] base : Internal Server Error: /
Traceback (most recent call last):
  File "/usr/local/lib/python2.7/dist-packages/django/core/handlers/base.py", line 119, in get_response
    resolver_match = resolver.resolve(request.path_info)
  File "/usr/local/lib/python2.7/dist-packages/django/core/urlresolvers.py", line 366, in resolve
    for pattern in self.url_patterns:
  File "/usr/local/lib/python2.7/dist-packages/django/core/urlresolvers.py", line 402, in url_patterns
    patterns = getattr(self.urlconf_module, "urlpatterns", self.urlconf_module)
  File "/usr/local/lib/python2.7/dist-packages/django/core/urlresolvers.py", line 396, in urlconf_module
    self._urlconf_module = import_module(self.urlconf_name)
  File "/usr/lib/python2.7/importlib/__init__.py", line 37, in import_module
    __import__(name)
  File "/root/levysys/vmaig_blog/vmaig_blog/urls.py", line 14, in <module>
    url(r'^media/(?P<path>.*)$','django.views.static.serve',{'document_root':setting.MEDIA_ROOT}),
NameError: name 'setting' is not defined
[2015-09-15 22:54:22,412] [ERROR] base : Internal Server Error: /
Traceback (most recent call last):
  File "/usr/local/lib/python2.7/dist-packages/django/core/handlers/base.py", line 119, in get_response
    resolver_match = resolver.resolve(request.path_info)
  File "/usr/local/lib/python2.7/dist-packages/django/core/urlresolvers.py", line 366, in resolve
    for pattern in self.url_patterns:
  File "/usr/local/lib/python2.7/dist-packages/django/core/urlresolvers.py", line 402, in url_patterns
    patterns = getattr(self.urlconf_module, "urlpatterns", self.urlconf_module)
  File "/usr/local/lib/python2.7/dist-packages/django/core/urlresolvers.py", line 396, in urlconf_module
    self._urlconf_module = import_module(self.urlconf_name)
  File "/usr/lib/python2.7/importlib/__init__.py", line 37, in import_module
    __import__(name)
  File "/root/levysys/vmaig_blog/vmaig_blog/urls.py", line 14, in <module>
    url(r'^media/(?P<path>.*)$','django.views.static.serve',{'document_root':setting.MEDIA_ROOT}),
NameError: name 'setting' is not defined
[2015-09-15 22:54:47,621] [ERROR] base : Internal Server Error: /media/static/carousel/1.jpg
Traceback (most recent call last):
  File "/usr/local/lib/python2.7/dist-packages/django/core/handlers/base.py", line 108, in get_response
    response = middleware_method(request)
  File "/usr/local/lib/python2.7/dist-packages/django/middleware/common.py", line 74, in process_request
    if (not urlresolvers.is_valid_path(request.path_info, urlconf) and
  File "/usr/local/lib/python2.7/dist-packages/django/core/urlresolvers.py", line 647, in is_valid_path
    resolve(path, urlconf)
  File "/usr/local/lib/python2.7/dist-packages/django/core/urlresolvers.py", line 522, in resolve
    return get_resolver(urlconf).resolve(path)
  File "/usr/local/lib/python2.7/dist-packages/django/core/urlresolvers.py", line 366, in resolve
    for pattern in self.url_patterns:
  File "/usr/local/lib/python2.7/dist-packages/django/core/urlresolvers.py", line 402, in url_patterns
    patterns = getattr(self.urlconf_module, "urlpatterns", self.urlconf_module)
  File "/usr/local/lib/python2.7/dist-packages/django/core/urlresolvers.py", line 396, in urlconf_module
    self._urlconf_module = import_module(self.urlconf_name)
  File "/usr/lib/python2.7/importlib/__init__.py", line 37, in import_module
    __import__(name)
  File "/root/levysys/vmaig_blog/vmaig_blog/urls.py", line 14, in <module>
    url(r'^media/(?P<path>.*)$','django.views.static.serve',{'document_root':settings.MEDIA_ROOT}),
NameError: name 'settings' is not defined
[2015-09-15 22:54:47,621] [ERROR] base : Internal Server Error: /media/static/carousel/1.jpg
Traceback (most recent call last):
  File "/usr/local/lib/python2.7/dist-packages/django/core/handlers/base.py", line 108, in get_response
    response = middleware_method(request)
  File "/usr/local/lib/python2.7/dist-packages/django/middleware/common.py", line 74, in process_request
    if (not urlresolvers.is_valid_path(request.path_info, urlconf) and
  File "/usr/local/lib/python2.7/dist-packages/django/core/urlresolvers.py", line 647, in is_valid_path
    resolve(path, urlconf)
  File "/usr/local/lib/python2.7/dist-packages/django/core/urlresolvers.py", line 522, in resolve
    return get_resolver(urlconf).resolve(path)
  File "/usr/local/lib/python2.7/dist-packages/django/core/urlresolvers.py", line 366, in resolve
    for pattern in self.url_patterns:
  File "/usr/local/lib/python2.7/dist-packages/django/core/urlresolvers.py", line 402, in url_patterns
    patterns = getattr(self.urlconf_module, "urlpatterns", self.urlconf_module)
  File "/usr/local/lib/python2.7/dist-packages/django/core/urlresolvers.py", line 396, in urlconf_module
    self._urlconf_module = import_module(self.urlconf_name)
  File "/usr/lib/python2.7/importlib/__init__.py", line 37, in import_module
    __import__(name)
  File "/root/levysys/vmaig_blog/vmaig_blog/urls.py", line 14, in <module>
    url(r'^media/(?P<path>.*)$','django.views.static.serve',{'document_root':settings.MEDIA_ROOT}),
NameError: name 'settings' is not defined
[2015-09-15 22:55:45,827] [ERROR] base : Internal Server Error: /media/static/carousel/1.jpg
Traceback (most recent call last):
  File "/usr/local/lib/python2.7/dist-packages/django/core/handlers/base.py", line 108, in get_response
    response = middleware_method(request)
  File "/usr/local/lib/python2.7/dist-packages/django/middleware/common.py", line 74, in process_request
    if (not urlresolvers.is_valid_path(request.path_info, urlconf) and
  File "/usr/local/lib/python2.7/dist-packages/django/core/urlresolvers.py", line 647, in is_valid_path
    resolve(path, urlconf)
  File "/usr/local/lib/python2.7/dist-packages/django/core/urlresolvers.py", line 522, in resolve
    return get_resolver(urlconf).resolve(path)
  File "/usr/local/lib/python2.7/dist-packages/django/core/urlresolvers.py", line 366, in resolve
    for pattern in self.url_patterns:
  File "/usr/local/lib/python2.7/dist-packages/django/core/urlresolvers.py", line 402, in url_patterns
    patterns = getattr(self.urlconf_module, "urlpatterns", self.urlconf_module)
  File "/usr/local/lib/python2.7/dist-packages/django/core/urlresolvers.py", line 396, in urlconf_module
    self._urlconf_module = import_module(self.urlconf_name)
  File "/usr/lib/python2.7/importlib/__init__.py", line 37, in import_module
    __import__(name)
  File "/root/levysys/vmaig_blog/vmaig_blog/urls.py", line 14, in <module>
    url(r'^media/(?P<path>.*)$','django.views.static.serve',{'document_root':vmaig_blog.settings.MEDIA_ROOT}),
NameError: name 'vmaig_blog' is not defined
[2015-09-15 22:55:45,827] [ERROR] base : Internal Server Error: /media/static/carousel/1.jpg
Traceback (most recent call last):
  File "/usr/local/lib/python2.7/dist-packages/django/core/handlers/base.py", line 108, in get_response
    response = middleware_method(request)
  File "/usr/local/lib/python2.7/dist-packages/django/middleware/common.py", line 74, in process_request
    if (not urlresolvers.is_valid_path(request.path_info, urlconf) and
  File "/usr/local/lib/python2.7/dist-packages/django/core/urlresolvers.py", line 647, in is_valid_path
    resolve(path, urlconf)
  File "/usr/local/lib/python2.7/dist-packages/django/core/urlresolvers.py", line 522, in resolve
    return get_resolver(urlconf).resolve(path)
  File "/usr/local/lib/python2.7/dist-packages/django/core/urlresolvers.py", line 366, in resolve
    for pattern in self.url_patterns:
  File "/usr/local/lib/python2.7/dist-packages/django/core/urlresolvers.py", line 402, in url_patterns
    patterns = getattr(self.urlconf_module, "urlpatterns", self.urlconf_module)
  File "/usr/local/lib/python2.7/dist-packages/django/core/urlresolvers.py", line 396, in urlconf_module
    self._urlconf_module = import_module(self.urlconf_name)
  File "/usr/lib/python2.7/importlib/__init__.py", line 37, in import_module
    __import__(name)
  File "/root/levysys/vmaig_blog/vmaig_blog/urls.py", line 14, in <module>
    url(r'^media/(?P<path>.*)$','django.views.static.serve',{'document_root':vmaig_blog.settings.MEDIA_ROOT}),
NameError: name 'vmaig_blog' is not defined
[2015-09-15 22:56:58,068] [ERROR] base : Internal Server Error: /media/static/carousel/1.jpg
Traceback (most recent call last):
  File "/usr/local/lib/python2.7/dist-packages/django/core/handlers/base.py", line 108, in get_response
    response = middleware_method(request)
  File "/usr/local/lib/python2.7/dist-packages/django/middleware/common.py", line 74, in process_request
    if (not urlresolvers.is_valid_path(request.path_info, urlconf) and
  File "/usr/local/lib/python2.7/dist-packages/django/core/urlresolvers.py", line 647, in is_valid_path
    resolve(path, urlconf)
  File "/usr/local/lib/python2.7/dist-packages/django/core/urlresolvers.py", line 522, in resolve
    return get_resolver(urlconf).resolve(path)
  File "/usr/local/lib/python2.7/dist-packages/django/core/urlresolvers.py", line 366, in resolve
    for pattern in self.url_patterns:
  File "/usr/local/lib/python2.7/dist-packages/django/core/urlresolvers.py", line 402, in url_patterns
    patterns = getattr(self.urlconf_module, "urlpatterns", self.urlconf_module)
  File "/usr/local/lib/python2.7/dist-packages/django/core/urlresolvers.py", line 396, in urlconf_module
    self._urlconf_module = import_module(self.urlconf_name)
  File "/usr/lib/python2.7/importlib/__init__.py", line 37, in import_module
    __import__(name)
  File "/root/levysys/vmaig_blog/vmaig_blog/urls.py", line 14, in <module>
    url(r'^media/(?P<path>.*)$','django.views.static.serve',{'document_root':MEDIA_ROOT}),
NameError: name 'MEDIA_ROOT' is not defined
[2015-09-15 22:56:58,068] [ERROR] base : Internal Server Error: /media/static/carousel/1.jpg
Traceback (most recent call last):
  File "/usr/local/lib/python2.7/dist-packages/django/core/handlers/base.py", line 108, in get_response
    response = middleware_method(request)
  File "/usr/local/lib/python2.7/dist-packages/django/middleware/common.py", line 74, in process_request
    if (not urlresolvers.is_valid_path(request.path_info, urlconf) and
  File "/usr/local/lib/python2.7/dist-packages/django/core/urlresolvers.py", line 647, in is_valid_path
    resolve(path, urlconf)
  File "/usr/local/lib/python2.7/dist-packages/django/core/urlresolvers.py", line 522, in resolve
    return get_resolver(urlconf).resolve(path)
  File "/usr/local/lib/python2.7/dist-packages/django/core/urlresolvers.py", line 366, in resolve
    for pattern in self.url_patterns:
  File "/usr/local/lib/python2.7/dist-packages/django/core/urlresolvers.py", line 402, in url_patterns
    patterns = getattr(self.urlconf_module, "urlpatterns", self.urlconf_module)
  File "/usr/local/lib/python2.7/dist-packages/django/core/urlresolvers.py", line 396, in urlconf_module
    self._urlconf_module = import_module(self.urlconf_name)
  File "/usr/lib/python2.7/importlib/__init__.py", line 37, in import_module
    __import__(name)
  File "/root/levysys/vmaig_blog/vmaig_blog/urls.py", line 14, in <module>
    url(r'^media/(?P<path>.*)$','django.views.static.serve',{'document_root':MEDIA_ROOT}),
NameError: name 'MEDIA_ROOT' is not defined
